Traceback (most recent call last):
  File "/opt/homebrew/anaconda3/envs/capstone/lib/python3.8/site-packages/wandb/sdk/wandb_config.py", line 165, in __getattr__
    return self.__getitem__(key)
  File "/opt/homebrew/anaconda3/envs/capstone/lib/python3.8/site-packages/wandb/sdk/wandb_config.py", line 130, in __getitem__
    return self._items[key]
KeyError: 'num_transformer_layers'

The above exception was the direct cause of the following exception:

Traceback (most recent call last):
  File "/Users/gichanpark/Desktop/castone_design/finger_printing/train_CNNTransformer_sweep.py", line 137, in train_model
    num_transformer_layers=config.num_transformer_layers,
  File "/opt/homebrew/anaconda3/envs/capstone/lib/python3.8/site-packages/wandb/sdk/wandb_config.py", line 167, in __getattr__
    raise AttributeError(
AttributeError: <class 'wandb.sdk.wandb_config.Config'> object has no attribute 'num_transformer_layers'
