2025-03-30 00:54:14,798 INFO    MainThread:83519 [wandb_setup.py:_flush():67] Current SDK version is 0.19.8
2025-03-30 00:54:14,798 INFO    MainThread:83519 [wandb_setup.py:_flush():67] Configure stats pid to 83519
2025-03-30 00:54:14,799 INFO    MainThread:83519 [wandb_setup.py:_flush():67] Loading settings from /Users/gichanpark/.config/wandb/settings
2025-03-30 00:54:14,799 INFO    MainThread:83519 [wandb_setup.py:_flush():67] Loading settings from /Users/gichanpark/Desktop/castone_design/wandb/settings
2025-03-30 00:54:14,799 INFO    MainThread:83519 [wandb_setup.py:_flush():67] Loading settings from environment variables
2025-03-30 00:54:14,799 INFO    MainThread:83519 [wandb_init.py:setup_run_log_directory():647] Logging user logs to /Users/gichanpark/Desktop/castone_design/wandb/run-20250330_005414-jfqm387t/logs/debug.log
2025-03-30 00:54:14,799 INFO    MainThread:83519 [wandb_init.py:setup_run_log_directory():648] Logging internal logs to /Users/gichanpark/Desktop/castone_design/wandb/run-20250330_005414-jfqm387t/logs/debug-internal.log
2025-03-30 00:54:14,799 INFO    MainThread:83519 [wandb_init.py:init():761] calling init triggers
2025-03-30 00:54:14,799 INFO    MainThread:83519 [wandb_init.py:init():766] wandb.init called with sweep_config: {}
config: {'_wandb': {}}
2025-03-30 00:54:14,799 INFO    MainThread:83519 [wandb_init.py:init():784] starting backend
2025-03-30 00:54:14,799 INFO    MainThread:83519 [wandb_init.py:init():788] sending inform_init request
2025-03-30 00:54:14,831 INFO    MainThread:83519 [backend.py:_multiprocessing_setup():101] multiprocessing start_methods=spawn,fork,forkserver, using: spawn
2025-03-30 00:54:14,831 INFO    MainThread:83519 [wandb_init.py:init():798] backend started and connected
2025-03-30 00:54:14,835 INFO    MainThread:83519 [wandb_init.py:init():891] updated telemetry
2025-03-30 00:54:14,853 INFO    MainThread:83519 [wandb_init.py:init():915] communicating run to backend with 90.0 second timeout
2025-03-30 00:54:15,283 INFO    MainThread:83519 [wandb_init.py:init():990] starting run threads in backend
2025-03-30 00:54:15,352 INFO    MainThread:83519 [wandb_run.py:_console_start():2375] atexit reg
2025-03-30 00:54:15,352 INFO    MainThread:83519 [wandb_run.py:_redirect():2227] redirect: wrap_raw
2025-03-30 00:54:15,352 INFO    MainThread:83519 [wandb_run.py:_redirect():2292] Wrapping output streams.
2025-03-30 00:54:15,352 INFO    MainThread:83519 [wandb_run.py:_redirect():2315] Redirects installed.
2025-03-30 00:54:15,354 INFO    MainThread:83519 [wandb_init.py:init():1032] run started, returning control to user process
2025-03-30 00:54:15,354 INFO    MainThread:83519 [wandb_run.py:_config_callback():1261] config_cb None None {'epochs': 10000, 'early_stopping': False, 'model': 'WifiCNNTransformer'}
2025-03-30 02:00:59,101 INFO    MsgRouterThr:83519 [mailbox.py:close():129] Closing mailbox, abandoning 1 handles.
2025-03-30 02:00:59,453 ERROR   MainThread:83519 [redirect.py:_on_write():661] error in stderr callback
Traceback (most recent call last):
  File "/opt/homebrew/anaconda3/envs/capstone/lib/python3.8/site-packages/wandb/sdk/lib/redirect.py", line 659, in _on_write
    cb(written_data)
  File "/opt/homebrew/anaconda3/envs/capstone/lib/python3.8/site-packages/wandb/sdk/wandb_run.py", line 2302, in <lambda>
    lambda data: self._console_raw_callback("stderr", data),
  File "/opt/homebrew/anaconda3/envs/capstone/lib/python3.8/site-packages/wandb/sdk/wandb_run.py", line 401, in wrapper_fn
    return func(self, *args, **kwargs)
  File "/opt/homebrew/anaconda3/envs/capstone/lib/python3.8/site-packages/wandb/sdk/wandb_run.py", line 1444, in _console_raw_callback
    self._backend.interface.publish_output_raw(name, data)
  File "/opt/homebrew/anaconda3/envs/capstone/lib/python3.8/site-packages/wandb/sdk/interface/interface.py", line 761, in publish_output_raw
    self._publish_output_raw(o)
  File "/opt/homebrew/anaconda3/envs/capstone/lib/python3.8/site-packages/wandb/sdk/interface/interface_shared.py", line 38, in _publish_output_raw
    self._publish(rec)
  File "/opt/homebrew/anaconda3/envs/capstone/lib/python3.8/site-packages/wandb/sdk/interface/interface_sock.py", line 39, in _publish
    self._sock_client.send_record_publish(record)
  File "/opt/homebrew/anaconda3/envs/capstone/lib/python3.8/site-packages/wandb/sdk/lib/sock_client.py", line 174, in send_record_publish
    self.send_server_request(server_req)
  File "/opt/homebrew/anaconda3/envs/capstone/lib/python3.8/site-packages/wandb/sdk/lib/sock_client.py", line 154, in send_server_request
    self._send_message(msg)
  File "/opt/homebrew/anaconda3/envs/capstone/lib/python3.8/site-packages/wandb/sdk/lib/sock_client.py", line 151, in _send_message
    self._sendall_with_error_handle(header + data)
  File "/opt/homebrew/anaconda3/envs/capstone/lib/python3.8/site-packages/wandb/sdk/lib/sock_client.py", line 130, in _sendall_with_error_handle
    sent = self._sock.send(data)
BrokenPipeError: [Errno 32] Broken pipe
2025-03-30 02:00:59,458 ERROR   MainThread:83519 [redirect.py:_on_write():661] error in stderr callback
Traceback (most recent call last):
  File "/opt/homebrew/anaconda3/envs/capstone/lib/python3.8/site-packages/wandb/sdk/lib/redirect.py", line 659, in _on_write
    cb(written_data)
  File "/opt/homebrew/anaconda3/envs/capstone/lib/python3.8/site-packages/wandb/sdk/wandb_run.py", line 2302, in <lambda>
    lambda data: self._console_raw_callback("stderr", data),
  File "/opt/homebrew/anaconda3/envs/capstone/lib/python3.8/site-packages/wandb/sdk/wandb_run.py", line 401, in wrapper_fn
    return func(self, *args, **kwargs)
  File "/opt/homebrew/anaconda3/envs/capstone/lib/python3.8/site-packages/wandb/sdk/wandb_run.py", line 1444, in _console_raw_callback
    self._backend.interface.publish_output_raw(name, data)
  File "/opt/homebrew/anaconda3/envs/capstone/lib/python3.8/site-packages/wandb/sdk/interface/interface.py", line 761, in publish_output_raw
    self._publish_output_raw(o)
  File "/opt/homebrew/anaconda3/envs/capstone/lib/python3.8/site-packages/wandb/sdk/interface/interface_shared.py", line 38, in _publish_output_raw
    self._publish(rec)
  File "/opt/homebrew/anaconda3/envs/capstone/lib/python3.8/site-packages/wandb/sdk/interface/interface_sock.py", line 39, in _publish
    self._sock_client.send_record_publish(record)
  File "/opt/homebrew/anaconda3/envs/capstone/lib/python3.8/site-packages/wandb/sdk/lib/sock_client.py", line 174, in send_record_publish
    self.send_server_request(server_req)
  File "/opt/homebrew/anaconda3/envs/capstone/lib/python3.8/site-packages/wandb/sdk/lib/sock_client.py", line 154, in send_server_request
    self._send_message(msg)
  File "/opt/homebrew/anaconda3/envs/capstone/lib/python3.8/site-packages/wandb/sdk/lib/sock_client.py", line 151, in _send_message
    self._sendall_with_error_handle(header + data)
  File "/opt/homebrew/anaconda3/envs/capstone/lib/python3.8/site-packages/wandb/sdk/lib/sock_client.py", line 130, in _sendall_with_error_handle
    sent = self._sock.send(data)
BrokenPipeError: [Errno 32] Broken pipe
2025-03-30 02:00:59,460 ERROR   MainThread:83519 [redirect.py:_on_write():661] error in stderr callback
Traceback (most recent call last):
  File "/opt/homebrew/anaconda3/envs/capstone/lib/python3.8/site-packages/wandb/sdk/lib/redirect.py", line 659, in _on_write
    cb(written_data)
  File "/opt/homebrew/anaconda3/envs/capstone/lib/python3.8/site-packages/wandb/sdk/wandb_run.py", line 2302, in <lambda>
    lambda data: self._console_raw_callback("stderr", data),
  File "/opt/homebrew/anaconda3/envs/capstone/lib/python3.8/site-packages/wandb/sdk/wandb_run.py", line 401, in wrapper_fn
    return func(self, *args, **kwargs)
  File "/opt/homebrew/anaconda3/envs/capstone/lib/python3.8/site-packages/wandb/sdk/wandb_run.py", line 1444, in _console_raw_callback
    self._backend.interface.publish_output_raw(name, data)
  File "/opt/homebrew/anaconda3/envs/capstone/lib/python3.8/site-packages/wandb/sdk/interface/interface.py", line 761, in publish_output_raw
    self._publish_output_raw(o)
  File "/opt/homebrew/anaconda3/envs/capstone/lib/python3.8/site-packages/wandb/sdk/interface/interface_shared.py", line 38, in _publish_output_raw
    self._publish(rec)
  File "/opt/homebrew/anaconda3/envs/capstone/lib/python3.8/site-packages/wandb/sdk/interface/interface_sock.py", line 39, in _publish
    self._sock_client.send_record_publish(record)
  File "/opt/homebrew/anaconda3/envs/capstone/lib/python3.8/site-packages/wandb/sdk/lib/sock_client.py", line 174, in send_record_publish
    self.send_server_request(server_req)
  File "/opt/homebrew/anaconda3/envs/capstone/lib/python3.8/site-packages/wandb/sdk/lib/sock_client.py", line 154, in send_server_request
    self._send_message(msg)
  File "/opt/homebrew/anaconda3/envs/capstone/lib/python3.8/site-packages/wandb/sdk/lib/sock_client.py", line 151, in _send_message
    self._sendall_with_error_handle(header + data)
  File "/opt/homebrew/anaconda3/envs/capstone/lib/python3.8/site-packages/wandb/sdk/lib/sock_client.py", line 130, in _sendall_with_error_handle
    sent = self._sock.send(data)
BrokenPipeError: [Errno 32] Broken pipe
2025-03-30 02:00:59,460 ERROR   MainThread:83519 [redirect.py:_on_write():661] error in stderr callback
Traceback (most recent call last):
  File "/opt/homebrew/anaconda3/envs/capstone/lib/python3.8/site-packages/wandb/sdk/lib/redirect.py", line 659, in _on_write
    cb(written_data)
  File "/opt/homebrew/anaconda3/envs/capstone/lib/python3.8/site-packages/wandb/sdk/wandb_run.py", line 2302, in <lambda>
    lambda data: self._console_raw_callback("stderr", data),
  File "/opt/homebrew/anaconda3/envs/capstone/lib/python3.8/site-packages/wandb/sdk/wandb_run.py", line 401, in wrapper_fn
    return func(self, *args, **kwargs)
  File "/opt/homebrew/anaconda3/envs/capstone/lib/python3.8/site-packages/wandb/sdk/wandb_run.py", line 1444, in _console_raw_callback
    self._backend.interface.publish_output_raw(name, data)
  File "/opt/homebrew/anaconda3/envs/capstone/lib/python3.8/site-packages/wandb/sdk/interface/interface.py", line 761, in publish_output_raw
    self._publish_output_raw(o)
  File "/opt/homebrew/anaconda3/envs/capstone/lib/python3.8/site-packages/wandb/sdk/interface/interface_shared.py", line 38, in _publish_output_raw
    self._publish(rec)
  File "/opt/homebrew/anaconda3/envs/capstone/lib/python3.8/site-packages/wandb/sdk/interface/interface_sock.py", line 39, in _publish
    self._sock_client.send_record_publish(record)
  File "/opt/homebrew/anaconda3/envs/capstone/lib/python3.8/site-packages/wandb/sdk/lib/sock_client.py", line 174, in send_record_publish
    self.send_server_request(server_req)
  File "/opt/homebrew/anaconda3/envs/capstone/lib/python3.8/site-packages/wandb/sdk/lib/sock_client.py", line 154, in send_server_request
    self._send_message(msg)
  File "/opt/homebrew/anaconda3/envs/capstone/lib/python3.8/site-packages/wandb/sdk/lib/sock_client.py", line 151, in _send_message
    self._sendall_with_error_handle(header + data)
  File "/opt/homebrew/anaconda3/envs/capstone/lib/python3.8/site-packages/wandb/sdk/lib/sock_client.py", line 130, in _sendall_with_error_handle
    sent = self._sock.send(data)
BrokenPipeError: [Errno 32] Broken pipe
2025-03-30 02:00:59,460 ERROR   MainThread:83519 [redirect.py:_on_write():661] error in stderr callback
Traceback (most recent call last):
  File "/opt/homebrew/anaconda3/envs/capstone/lib/python3.8/site-packages/wandb/sdk/lib/redirect.py", line 659, in _on_write
    cb(written_data)
  File "/opt/homebrew/anaconda3/envs/capstone/lib/python3.8/site-packages/wandb/sdk/wandb_run.py", line 2302, in <lambda>
    lambda data: self._console_raw_callback("stderr", data),
  File "/opt/homebrew/anaconda3/envs/capstone/lib/python3.8/site-packages/wandb/sdk/wandb_run.py", line 401, in wrapper_fn
    return func(self, *args, **kwargs)
  File "/opt/homebrew/anaconda3/envs/capstone/lib/python3.8/site-packages/wandb/sdk/wandb_run.py", line 1444, in _console_raw_callback
    self._backend.interface.publish_output_raw(name, data)
  File "/opt/homebrew/anaconda3/envs/capstone/lib/python3.8/site-packages/wandb/sdk/interface/interface.py", line 761, in publish_output_raw
    self._publish_output_raw(o)
  File "/opt/homebrew/anaconda3/envs/capstone/lib/python3.8/site-packages/wandb/sdk/interface/interface_shared.py", line 38, in _publish_output_raw
    self._publish(rec)
  File "/opt/homebrew/anaconda3/envs/capstone/lib/python3.8/site-packages/wandb/sdk/interface/interface_sock.py", line 39, in _publish
    self._sock_client.send_record_publish(record)
  File "/opt/homebrew/anaconda3/envs/capstone/lib/python3.8/site-packages/wandb/sdk/lib/sock_client.py", line 174, in send_record_publish
    self.send_server_request(server_req)
  File "/opt/homebrew/anaconda3/envs/capstone/lib/python3.8/site-packages/wandb/sdk/lib/sock_client.py", line 154, in send_server_request
    self._send_message(msg)
  File "/opt/homebrew/anaconda3/envs/capstone/lib/python3.8/site-packages/wandb/sdk/lib/sock_client.py", line 151, in _send_message
    self._sendall_with_error_handle(header + data)
  File "/opt/homebrew/anaconda3/envs/capstone/lib/python3.8/site-packages/wandb/sdk/lib/sock_client.py", line 130, in _sendall_with_error_handle
    sent = self._sock.send(data)
BrokenPipeError: [Errno 32] Broken pipe
2025-03-30 02:00:59,461 ERROR   MainThread:83519 [redirect.py:_on_write():661] error in stderr callback
Traceback (most recent call last):
  File "/opt/homebrew/anaconda3/envs/capstone/lib/python3.8/site-packages/wandb/sdk/lib/redirect.py", line 659, in _on_write
    cb(written_data)
  File "/opt/homebrew/anaconda3/envs/capstone/lib/python3.8/site-packages/wandb/sdk/wandb_run.py", line 2302, in <lambda>
    lambda data: self._console_raw_callback("stderr", data),
  File "/opt/homebrew/anaconda3/envs/capstone/lib/python3.8/site-packages/wandb/sdk/wandb_run.py", line 401, in wrapper_fn
    return func(self, *args, **kwargs)
  File "/opt/homebrew/anaconda3/envs/capstone/lib/python3.8/site-packages/wandb/sdk/wandb_run.py", line 1444, in _console_raw_callback
    self._backend.interface.publish_output_raw(name, data)
  File "/opt/homebrew/anaconda3/envs/capstone/lib/python3.8/site-packages/wandb/sdk/interface/interface.py", line 761, in publish_output_raw
    self._publish_output_raw(o)
  File "/opt/homebrew/anaconda3/envs/capstone/lib/python3.8/site-packages/wandb/sdk/interface/interface_shared.py", line 38, in _publish_output_raw
    self._publish(rec)
  File "/opt/homebrew/anaconda3/envs/capstone/lib/python3.8/site-packages/wandb/sdk/interface/interface_sock.py", line 39, in _publish
    self._sock_client.send_record_publish(record)
  File "/opt/homebrew/anaconda3/envs/capstone/lib/python3.8/site-packages/wandb/sdk/lib/sock_client.py", line 174, in send_record_publish
    self.send_server_request(server_req)
  File "/opt/homebrew/anaconda3/envs/capstone/lib/python3.8/site-packages/wandb/sdk/lib/sock_client.py", line 154, in send_server_request
    self._send_message(msg)
  File "/opt/homebrew/anaconda3/envs/capstone/lib/python3.8/site-packages/wandb/sdk/lib/sock_client.py", line 151, in _send_message
    self._sendall_with_error_handle(header + data)
  File "/opt/homebrew/anaconda3/envs/capstone/lib/python3.8/site-packages/wandb/sdk/lib/sock_client.py", line 130, in _sendall_with_error_handle
    sent = self._sock.send(data)
BrokenPipeError: [Errno 32] Broken pipe
2025-03-30 02:00:59,461 ERROR   MainThread:83519 [redirect.py:_on_write():661] error in stderr callback
Traceback (most recent call last):
  File "/opt/homebrew/anaconda3/envs/capstone/lib/python3.8/site-packages/wandb/sdk/lib/redirect.py", line 659, in _on_write
    cb(written_data)
  File "/opt/homebrew/anaconda3/envs/capstone/lib/python3.8/site-packages/wandb/sdk/wandb_run.py", line 2302, in <lambda>
    lambda data: self._console_raw_callback("stderr", data),
  File "/opt/homebrew/anaconda3/envs/capstone/lib/python3.8/site-packages/wandb/sdk/wandb_run.py", line 401, in wrapper_fn
    return func(self, *args, **kwargs)
  File "/opt/homebrew/anaconda3/envs/capstone/lib/python3.8/site-packages/wandb/sdk/wandb_run.py", line 1444, in _console_raw_callback
    self._backend.interface.publish_output_raw(name, data)
  File "/opt/homebrew/anaconda3/envs/capstone/lib/python3.8/site-packages/wandb/sdk/interface/interface.py", line 761, in publish_output_raw
    self._publish_output_raw(o)
  File "/opt/homebrew/anaconda3/envs/capstone/lib/python3.8/site-packages/wandb/sdk/interface/interface_shared.py", line 38, in _publish_output_raw
    self._publish(rec)
  File "/opt/homebrew/anaconda3/envs/capstone/lib/python3.8/site-packages/wandb/sdk/interface/interface_sock.py", line 39, in _publish
    self._sock_client.send_record_publish(record)
  File "/opt/homebrew/anaconda3/envs/capstone/lib/python3.8/site-packages/wandb/sdk/lib/sock_client.py", line 174, in send_record_publish
    self.send_server_request(server_req)
  File "/opt/homebrew/anaconda3/envs/capstone/lib/python3.8/site-packages/wandb/sdk/lib/sock_client.py", line 154, in send_server_request
    self._send_message(msg)
  File "/opt/homebrew/anaconda3/envs/capstone/lib/python3.8/site-packages/wandb/sdk/lib/sock_client.py", line 151, in _send_message
    self._sendall_with_error_handle(header + data)
  File "/opt/homebrew/anaconda3/envs/capstone/lib/python3.8/site-packages/wandb/sdk/lib/sock_client.py", line 130, in _sendall_with_error_handle
    sent = self._sock.send(data)
BrokenPipeError: [Errno 32] Broken pipe
2025-03-30 02:00:59,462 ERROR   MainThread:83519 [redirect.py:_on_write():661] error in stderr callback
Traceback (most recent call last):
  File "/opt/homebrew/anaconda3/envs/capstone/lib/python3.8/site-packages/wandb/sdk/lib/redirect.py", line 659, in _on_write
    cb(written_data)
  File "/opt/homebrew/anaconda3/envs/capstone/lib/python3.8/site-packages/wandb/sdk/wandb_run.py", line 2302, in <lambda>
    lambda data: self._console_raw_callback("stderr", data),
  File "/opt/homebrew/anaconda3/envs/capstone/lib/python3.8/site-packages/wandb/sdk/wandb_run.py", line 401, in wrapper_fn
    return func(self, *args, **kwargs)
  File "/opt/homebrew/anaconda3/envs/capstone/lib/python3.8/site-packages/wandb/sdk/wandb_run.py", line 1444, in _console_raw_callback
    self._backend.interface.publish_output_raw(name, data)
  File "/opt/homebrew/anaconda3/envs/capstone/lib/python3.8/site-packages/wandb/sdk/interface/interface.py", line 761, in publish_output_raw
    self._publish_output_raw(o)
  File "/opt/homebrew/anaconda3/envs/capstone/lib/python3.8/site-packages/wandb/sdk/interface/interface_shared.py", line 38, in _publish_output_raw
    self._publish(rec)
  File "/opt/homebrew/anaconda3/envs/capstone/lib/python3.8/site-packages/wandb/sdk/interface/interface_sock.py", line 39, in _publish
    self._sock_client.send_record_publish(record)
  File "/opt/homebrew/anaconda3/envs/capstone/lib/python3.8/site-packages/wandb/sdk/lib/sock_client.py", line 174, in send_record_publish
    self.send_server_request(server_req)
  File "/opt/homebrew/anaconda3/envs/capstone/lib/python3.8/site-packages/wandb/sdk/lib/sock_client.py", line 154, in send_server_request
    self._send_message(msg)
  File "/opt/homebrew/anaconda3/envs/capstone/lib/python3.8/site-packages/wandb/sdk/lib/sock_client.py", line 151, in _send_message
    self._sendall_with_error_handle(header + data)
  File "/opt/homebrew/anaconda3/envs/capstone/lib/python3.8/site-packages/wandb/sdk/lib/sock_client.py", line 130, in _sendall_with_error_handle
    sent = self._sock.send(data)
BrokenPipeError: [Errno 32] Broken pipe
2025-03-30 02:00:59,462 ERROR   MainThread:83519 [redirect.py:_on_write():661] error in stderr callback
Traceback (most recent call last):
  File "/opt/homebrew/anaconda3/envs/capstone/lib/python3.8/site-packages/wandb/sdk/lib/redirect.py", line 659, in _on_write
    cb(written_data)
  File "/opt/homebrew/anaconda3/envs/capstone/lib/python3.8/site-packages/wandb/sdk/wandb_run.py", line 2302, in <lambda>
    lambda data: self._console_raw_callback("stderr", data),
  File "/opt/homebrew/anaconda3/envs/capstone/lib/python3.8/site-packages/wandb/sdk/wandb_run.py", line 401, in wrapper_fn
    return func(self, *args, **kwargs)
  File "/opt/homebrew/anaconda3/envs/capstone/lib/python3.8/site-packages/wandb/sdk/wandb_run.py", line 1444, in _console_raw_callback
    self._backend.interface.publish_output_raw(name, data)
  File "/opt/homebrew/anaconda3/envs/capstone/lib/python3.8/site-packages/wandb/sdk/interface/interface.py", line 761, in publish_output_raw
    self._publish_output_raw(o)
  File "/opt/homebrew/anaconda3/envs/capstone/lib/python3.8/site-packages/wandb/sdk/interface/interface_shared.py", line 38, in _publish_output_raw
    self._publish(rec)
  File "/opt/homebrew/anaconda3/envs/capstone/lib/python3.8/site-packages/wandb/sdk/interface/interface_sock.py", line 39, in _publish
    self._sock_client.send_record_publish(record)
  File "/opt/homebrew/anaconda3/envs/capstone/lib/python3.8/site-packages/wandb/sdk/lib/sock_client.py", line 174, in send_record_publish
    self.send_server_request(server_req)
  File "/opt/homebrew/anaconda3/envs/capstone/lib/python3.8/site-packages/wandb/sdk/lib/sock_client.py", line 154, in send_server_request
    self._send_message(msg)
  File "/opt/homebrew/anaconda3/envs/capstone/lib/python3.8/site-packages/wandb/sdk/lib/sock_client.py", line 151, in _send_message
    self._sendall_with_error_handle(header + data)
  File "/opt/homebrew/anaconda3/envs/capstone/lib/python3.8/site-packages/wandb/sdk/lib/sock_client.py", line 130, in _sendall_with_error_handle
    sent = self._sock.send(data)
BrokenPipeError: [Errno 32] Broken pipe
2025-03-30 02:00:59,462 ERROR   MainThread:83519 [redirect.py:_on_write():661] error in stderr callback
Traceback (most recent call last):
  File "/opt/homebrew/anaconda3/envs/capstone/lib/python3.8/site-packages/wandb/sdk/lib/redirect.py", line 659, in _on_write
    cb(written_data)
  File "/opt/homebrew/anaconda3/envs/capstone/lib/python3.8/site-packages/wandb/sdk/wandb_run.py", line 2302, in <lambda>
    lambda data: self._console_raw_callback("stderr", data),
  File "/opt/homebrew/anaconda3/envs/capstone/lib/python3.8/site-packages/wandb/sdk/wandb_run.py", line 401, in wrapper_fn
    return func(self, *args, **kwargs)
  File "/opt/homebrew/anaconda3/envs/capstone/lib/python3.8/site-packages/wandb/sdk/wandb_run.py", line 1444, in _console_raw_callback
    self._backend.interface.publish_output_raw(name, data)
  File "/opt/homebrew/anaconda3/envs/capstone/lib/python3.8/site-packages/wandb/sdk/interface/interface.py", line 761, in publish_output_raw
    self._publish_output_raw(o)
  File "/opt/homebrew/anaconda3/envs/capstone/lib/python3.8/site-packages/wandb/sdk/interface/interface_shared.py", line 38, in _publish_output_raw
    self._publish(rec)
  File "/opt/homebrew/anaconda3/envs/capstone/lib/python3.8/site-packages/wandb/sdk/interface/interface_sock.py", line 39, in _publish
    self._sock_client.send_record_publish(record)
  File "/opt/homebrew/anaconda3/envs/capstone/lib/python3.8/site-packages/wandb/sdk/lib/sock_client.py", line 174, in send_record_publish
    self.send_server_request(server_req)
  File "/opt/homebrew/anaconda3/envs/capstone/lib/python3.8/site-packages/wandb/sdk/lib/sock_client.py", line 154, in send_server_request
    self._send_message(msg)
  File "/opt/homebrew/anaconda3/envs/capstone/lib/python3.8/site-packages/wandb/sdk/lib/sock_client.py", line 151, in _send_message
    self._sendall_with_error_handle(header + data)
  File "/opt/homebrew/anaconda3/envs/capstone/lib/python3.8/site-packages/wandb/sdk/lib/sock_client.py", line 130, in _sendall_with_error_handle
    sent = self._sock.send(data)
BrokenPipeError: [Errno 32] Broken pipe
2025-03-30 02:00:59,462 ERROR   MainThread:83519 [redirect.py:_on_write():661] error in stderr callback
Traceback (most recent call last):
  File "/opt/homebrew/anaconda3/envs/capstone/lib/python3.8/site-packages/wandb/sdk/lib/redirect.py", line 659, in _on_write
    cb(written_data)
  File "/opt/homebrew/anaconda3/envs/capstone/lib/python3.8/site-packages/wandb/sdk/wandb_run.py", line 2302, in <lambda>
    lambda data: self._console_raw_callback("stderr", data),
  File "/opt/homebrew/anaconda3/envs/capstone/lib/python3.8/site-packages/wandb/sdk/wandb_run.py", line 401, in wrapper_fn
    return func(self, *args, **kwargs)
  File "/opt/homebrew/anaconda3/envs/capstone/lib/python3.8/site-packages/wandb/sdk/wandb_run.py", line 1444, in _console_raw_callback
    self._backend.interface.publish_output_raw(name, data)
  File "/opt/homebrew/anaconda3/envs/capstone/lib/python3.8/site-packages/wandb/sdk/interface/interface.py", line 761, in publish_output_raw
    self._publish_output_raw(o)
  File "/opt/homebrew/anaconda3/envs/capstone/lib/python3.8/site-packages/wandb/sdk/interface/interface_shared.py", line 38, in _publish_output_raw
    self._publish(rec)
  File "/opt/homebrew/anaconda3/envs/capstone/lib/python3.8/site-packages/wandb/sdk/interface/interface_sock.py", line 39, in _publish
    self._sock_client.send_record_publish(record)
  File "/opt/homebrew/anaconda3/envs/capstone/lib/python3.8/site-packages/wandb/sdk/lib/sock_client.py", line 174, in send_record_publish
    self.send_server_request(server_req)
  File "/opt/homebrew/anaconda3/envs/capstone/lib/python3.8/site-packages/wandb/sdk/lib/sock_client.py", line 154, in send_server_request
    self._send_message(msg)
  File "/opt/homebrew/anaconda3/envs/capstone/lib/python3.8/site-packages/wandb/sdk/lib/sock_client.py", line 151, in _send_message
    self._sendall_with_error_handle(header + data)
  File "/opt/homebrew/anaconda3/envs/capstone/lib/python3.8/site-packages/wandb/sdk/lib/sock_client.py", line 130, in _sendall_with_error_handle
    sent = self._sock.send(data)
BrokenPipeError: [Errno 32] Broken pipe
2025-03-30 02:00:59,463 ERROR   MainThread:83519 [redirect.py:_on_write():661] error in stderr callback
Traceback (most recent call last):
  File "/opt/homebrew/anaconda3/envs/capstone/lib/python3.8/site-packages/wandb/sdk/lib/redirect.py", line 659, in _on_write
    cb(written_data)
  File "/opt/homebrew/anaconda3/envs/capstone/lib/python3.8/site-packages/wandb/sdk/wandb_run.py", line 2302, in <lambda>
    lambda data: self._console_raw_callback("stderr", data),
  File "/opt/homebrew/anaconda3/envs/capstone/lib/python3.8/site-packages/wandb/sdk/wandb_run.py", line 401, in wrapper_fn
    return func(self, *args, **kwargs)
  File "/opt/homebrew/anaconda3/envs/capstone/lib/python3.8/site-packages/wandb/sdk/wandb_run.py", line 1444, in _console_raw_callback
    self._backend.interface.publish_output_raw(name, data)
  File "/opt/homebrew/anaconda3/envs/capstone/lib/python3.8/site-packages/wandb/sdk/interface/interface.py", line 761, in publish_output_raw
    self._publish_output_raw(o)
  File "/opt/homebrew/anaconda3/envs/capstone/lib/python3.8/site-packages/wandb/sdk/interface/interface_shared.py", line 38, in _publish_output_raw
    self._publish(rec)
  File "/opt/homebrew/anaconda3/envs/capstone/lib/python3.8/site-packages/wandb/sdk/interface/interface_sock.py", line 39, in _publish
    self._sock_client.send_record_publish(record)
  File "/opt/homebrew/anaconda3/envs/capstone/lib/python3.8/site-packages/wandb/sdk/lib/sock_client.py", line 174, in send_record_publish
    self.send_server_request(server_req)
  File "/opt/homebrew/anaconda3/envs/capstone/lib/python3.8/site-packages/wandb/sdk/lib/sock_client.py", line 154, in send_server_request
    self._send_message(msg)
  File "/opt/homebrew/anaconda3/envs/capstone/lib/python3.8/site-packages/wandb/sdk/lib/sock_client.py", line 151, in _send_message
    self._sendall_with_error_handle(header + data)
  File "/opt/homebrew/anaconda3/envs/capstone/lib/python3.8/site-packages/wandb/sdk/lib/sock_client.py", line 130, in _sendall_with_error_handle
    sent = self._sock.send(data)
BrokenPipeError: [Errno 32] Broken pipe
2025-03-30 02:00:59,463 ERROR   MainThread:83519 [redirect.py:_on_write():661] error in stderr callback
Traceback (most recent call last):
  File "/opt/homebrew/anaconda3/envs/capstone/lib/python3.8/site-packages/wandb/sdk/lib/redirect.py", line 659, in _on_write
    cb(written_data)
  File "/opt/homebrew/anaconda3/envs/capstone/lib/python3.8/site-packages/wandb/sdk/wandb_run.py", line 2302, in <lambda>
    lambda data: self._console_raw_callback("stderr", data),
  File "/opt/homebrew/anaconda3/envs/capstone/lib/python3.8/site-packages/wandb/sdk/wandb_run.py", line 401, in wrapper_fn
    return func(self, *args, **kwargs)
  File "/opt/homebrew/anaconda3/envs/capstone/lib/python3.8/site-packages/wandb/sdk/wandb_run.py", line 1444, in _console_raw_callback
    self._backend.interface.publish_output_raw(name, data)
  File "/opt/homebrew/anaconda3/envs/capstone/lib/python3.8/site-packages/wandb/sdk/interface/interface.py", line 761, in publish_output_raw
    self._publish_output_raw(o)
  File "/opt/homebrew/anaconda3/envs/capstone/lib/python3.8/site-packages/wandb/sdk/interface/interface_shared.py", line 38, in _publish_output_raw
    self._publish(rec)
  File "/opt/homebrew/anaconda3/envs/capstone/lib/python3.8/site-packages/wandb/sdk/interface/interface_sock.py", line 39, in _publish
    self._sock_client.send_record_publish(record)
  File "/opt/homebrew/anaconda3/envs/capstone/lib/python3.8/site-packages/wandb/sdk/lib/sock_client.py", line 174, in send_record_publish
    self.send_server_request(server_req)
  File "/opt/homebrew/anaconda3/envs/capstone/lib/python3.8/site-packages/wandb/sdk/lib/sock_client.py", line 154, in send_server_request
    self._send_message(msg)
  File "/opt/homebrew/anaconda3/envs/capstone/lib/python3.8/site-packages/wandb/sdk/lib/sock_client.py", line 151, in _send_message
    self._sendall_with_error_handle(header + data)
  File "/opt/homebrew/anaconda3/envs/capstone/lib/python3.8/site-packages/wandb/sdk/lib/sock_client.py", line 130, in _sendall_with_error_handle
    sent = self._sock.send(data)
BrokenPipeError: [Errno 32] Broken pipe
2025-03-30 02:00:59,463 ERROR   MainThread:83519 [redirect.py:_on_write():661] error in stderr callback
Traceback (most recent call last):
  File "/opt/homebrew/anaconda3/envs/capstone/lib/python3.8/site-packages/wandb/sdk/lib/redirect.py", line 659, in _on_write
    cb(written_data)
  File "/opt/homebrew/anaconda3/envs/capstone/lib/python3.8/site-packages/wandb/sdk/wandb_run.py", line 2302, in <lambda>
    lambda data: self._console_raw_callback("stderr", data),
  File "/opt/homebrew/anaconda3/envs/capstone/lib/python3.8/site-packages/wandb/sdk/wandb_run.py", line 401, in wrapper_fn
    return func(self, *args, **kwargs)
  File "/opt/homebrew/anaconda3/envs/capstone/lib/python3.8/site-packages/wandb/sdk/wandb_run.py", line 1444, in _console_raw_callback
    self._backend.interface.publish_output_raw(name, data)
  File "/opt/homebrew/anaconda3/envs/capstone/lib/python3.8/site-packages/wandb/sdk/interface/interface.py", line 761, in publish_output_raw
    self._publish_output_raw(o)
  File "/opt/homebrew/anaconda3/envs/capstone/lib/python3.8/site-packages/wandb/sdk/interface/interface_shared.py", line 38, in _publish_output_raw
    self._publish(rec)
  File "/opt/homebrew/anaconda3/envs/capstone/lib/python3.8/site-packages/wandb/sdk/interface/interface_sock.py", line 39, in _publish
    self._sock_client.send_record_publish(record)
  File "/opt/homebrew/anaconda3/envs/capstone/lib/python3.8/site-packages/wandb/sdk/lib/sock_client.py", line 174, in send_record_publish
    self.send_server_request(server_req)
  File "/opt/homebrew/anaconda3/envs/capstone/lib/python3.8/site-packages/wandb/sdk/lib/sock_client.py", line 154, in send_server_request
    self._send_message(msg)
  File "/opt/homebrew/anaconda3/envs/capstone/lib/python3.8/site-packages/wandb/sdk/lib/sock_client.py", line 151, in _send_message
    self._sendall_with_error_handle(header + data)
  File "/opt/homebrew/anaconda3/envs/capstone/lib/python3.8/site-packages/wandb/sdk/lib/sock_client.py", line 130, in _sendall_with_error_handle
    sent = self._sock.send(data)
BrokenPipeError: [Errno 32] Broken pipe
2025-03-30 02:00:59,463 ERROR   MainThread:83519 [redirect.py:_on_write():661] error in stderr callback
Traceback (most recent call last):
  File "/opt/homebrew/anaconda3/envs/capstone/lib/python3.8/site-packages/wandb/sdk/lib/redirect.py", line 659, in _on_write
    cb(written_data)
  File "/opt/homebrew/anaconda3/envs/capstone/lib/python3.8/site-packages/wandb/sdk/wandb_run.py", line 2302, in <lambda>
    lambda data: self._console_raw_callback("stderr", data),
  File "/opt/homebrew/anaconda3/envs/capstone/lib/python3.8/site-packages/wandb/sdk/wandb_run.py", line 401, in wrapper_fn
    return func(self, *args, **kwargs)
  File "/opt/homebrew/anaconda3/envs/capstone/lib/python3.8/site-packages/wandb/sdk/wandb_run.py", line 1444, in _console_raw_callback
    self._backend.interface.publish_output_raw(name, data)
  File "/opt/homebrew/anaconda3/envs/capstone/lib/python3.8/site-packages/wandb/sdk/interface/interface.py", line 761, in publish_output_raw
    self._publish_output_raw(o)
  File "/opt/homebrew/anaconda3/envs/capstone/lib/python3.8/site-packages/wandb/sdk/interface/interface_shared.py", line 38, in _publish_output_raw
    self._publish(rec)
  File "/opt/homebrew/anaconda3/envs/capstone/lib/python3.8/site-packages/wandb/sdk/interface/interface_sock.py", line 39, in _publish
    self._sock_client.send_record_publish(record)
  File "/opt/homebrew/anaconda3/envs/capstone/lib/python3.8/site-packages/wandb/sdk/lib/sock_client.py", line 174, in send_record_publish
    self.send_server_request(server_req)
  File "/opt/homebrew/anaconda3/envs/capstone/lib/python3.8/site-packages/wandb/sdk/lib/sock_client.py", line 154, in send_server_request
    self._send_message(msg)
  File "/opt/homebrew/anaconda3/envs/capstone/lib/python3.8/site-packages/wandb/sdk/lib/sock_client.py", line 151, in _send_message
    self._sendall_with_error_handle(header + data)
  File "/opt/homebrew/anaconda3/envs/capstone/lib/python3.8/site-packages/wandb/sdk/lib/sock_client.py", line 130, in _sendall_with_error_handle
    sent = self._sock.send(data)
BrokenPipeError: [Errno 32] Broken pipe
2025-03-30 02:00:59,464 ERROR   MainThread:83519 [redirect.py:_on_write():661] error in stderr callback
Traceback (most recent call last):
  File "/opt/homebrew/anaconda3/envs/capstone/lib/python3.8/site-packages/wandb/sdk/lib/redirect.py", line 659, in _on_write
    cb(written_data)
  File "/opt/homebrew/anaconda3/envs/capstone/lib/python3.8/site-packages/wandb/sdk/wandb_run.py", line 2302, in <lambda>
    lambda data: self._console_raw_callback("stderr", data),
  File "/opt/homebrew/anaconda3/envs/capstone/lib/python3.8/site-packages/wandb/sdk/wandb_run.py", line 401, in wrapper_fn
    return func(self, *args, **kwargs)
  File "/opt/homebrew/anaconda3/envs/capstone/lib/python3.8/site-packages/wandb/sdk/wandb_run.py", line 1444, in _console_raw_callback
    self._backend.interface.publish_output_raw(name, data)
  File "/opt/homebrew/anaconda3/envs/capstone/lib/python3.8/site-packages/wandb/sdk/interface/interface.py", line 761, in publish_output_raw
    self._publish_output_raw(o)
  File "/opt/homebrew/anaconda3/envs/capstone/lib/python3.8/site-packages/wandb/sdk/interface/interface_shared.py", line 38, in _publish_output_raw
    self._publish(rec)
  File "/opt/homebrew/anaconda3/envs/capstone/lib/python3.8/site-packages/wandb/sdk/interface/interface_sock.py", line 39, in _publish
    self._sock_client.send_record_publish(record)
  File "/opt/homebrew/anaconda3/envs/capstone/lib/python3.8/site-packages/wandb/sdk/lib/sock_client.py", line 174, in send_record_publish
    self.send_server_request(server_req)
  File "/opt/homebrew/anaconda3/envs/capstone/lib/python3.8/site-packages/wandb/sdk/lib/sock_client.py", line 154, in send_server_request
    self._send_message(msg)
  File "/opt/homebrew/anaconda3/envs/capstone/lib/python3.8/site-packages/wandb/sdk/lib/sock_client.py", line 151, in _send_message
    self._sendall_with_error_handle(header + data)
  File "/opt/homebrew/anaconda3/envs/capstone/lib/python3.8/site-packages/wandb/sdk/lib/sock_client.py", line 130, in _sendall_with_error_handle
    sent = self._sock.send(data)
BrokenPipeError: [Errno 32] Broken pipe
2025-03-30 02:00:59,464 ERROR   MainThread:83519 [redirect.py:_on_write():661] error in stderr callback
Traceback (most recent call last):
  File "/opt/homebrew/anaconda3/envs/capstone/lib/python3.8/site-packages/wandb/sdk/lib/redirect.py", line 659, in _on_write
    cb(written_data)
  File "/opt/homebrew/anaconda3/envs/capstone/lib/python3.8/site-packages/wandb/sdk/wandb_run.py", line 2302, in <lambda>
    lambda data: self._console_raw_callback("stderr", data),
  File "/opt/homebrew/anaconda3/envs/capstone/lib/python3.8/site-packages/wandb/sdk/wandb_run.py", line 401, in wrapper_fn
    return func(self, *args, **kwargs)
  File "/opt/homebrew/anaconda3/envs/capstone/lib/python3.8/site-packages/wandb/sdk/wandb_run.py", line 1444, in _console_raw_callback
    self._backend.interface.publish_output_raw(name, data)
  File "/opt/homebrew/anaconda3/envs/capstone/lib/python3.8/site-packages/wandb/sdk/interface/interface.py", line 761, in publish_output_raw
    self._publish_output_raw(o)
  File "/opt/homebrew/anaconda3/envs/capstone/lib/python3.8/site-packages/wandb/sdk/interface/interface_shared.py", line 38, in _publish_output_raw
    self._publish(rec)
  File "/opt/homebrew/anaconda3/envs/capstone/lib/python3.8/site-packages/wandb/sdk/interface/interface_sock.py", line 39, in _publish
    self._sock_client.send_record_publish(record)
  File "/opt/homebrew/anaconda3/envs/capstone/lib/python3.8/site-packages/wandb/sdk/lib/sock_client.py", line 174, in send_record_publish
    self.send_server_request(server_req)
  File "/opt/homebrew/anaconda3/envs/capstone/lib/python3.8/site-packages/wandb/sdk/lib/sock_client.py", line 154, in send_server_request
    self._send_message(msg)
  File "/opt/homebrew/anaconda3/envs/capstone/lib/python3.8/site-packages/wandb/sdk/lib/sock_client.py", line 151, in _send_message
    self._sendall_with_error_handle(header + data)
  File "/opt/homebrew/anaconda3/envs/capstone/lib/python3.8/site-packages/wandb/sdk/lib/sock_client.py", line 130, in _sendall_with_error_handle
    sent = self._sock.send(data)
BrokenPipeError: [Errno 32] Broken pipe
2025-03-30 02:00:59,464 ERROR   MainThread:83519 [redirect.py:_on_write():661] error in stderr callback
Traceback (most recent call last):
  File "/opt/homebrew/anaconda3/envs/capstone/lib/python3.8/site-packages/wandb/sdk/lib/redirect.py", line 659, in _on_write
    cb(written_data)
  File "/opt/homebrew/anaconda3/envs/capstone/lib/python3.8/site-packages/wandb/sdk/wandb_run.py", line 2302, in <lambda>
    lambda data: self._console_raw_callback("stderr", data),
  File "/opt/homebrew/anaconda3/envs/capstone/lib/python3.8/site-packages/wandb/sdk/wandb_run.py", line 401, in wrapper_fn
    return func(self, *args, **kwargs)
  File "/opt/homebrew/anaconda3/envs/capstone/lib/python3.8/site-packages/wandb/sdk/wandb_run.py", line 1444, in _console_raw_callback
    self._backend.interface.publish_output_raw(name, data)
  File "/opt/homebrew/anaconda3/envs/capstone/lib/python3.8/site-packages/wandb/sdk/interface/interface.py", line 761, in publish_output_raw
    self._publish_output_raw(o)
  File "/opt/homebrew/anaconda3/envs/capstone/lib/python3.8/site-packages/wandb/sdk/interface/interface_shared.py", line 38, in _publish_output_raw
    self._publish(rec)
  File "/opt/homebrew/anaconda3/envs/capstone/lib/python3.8/site-packages/wandb/sdk/interface/interface_sock.py", line 39, in _publish
    self._sock_client.send_record_publish(record)
  File "/opt/homebrew/anaconda3/envs/capstone/lib/python3.8/site-packages/wandb/sdk/lib/sock_client.py", line 174, in send_record_publish
    self.send_server_request(server_req)
  File "/opt/homebrew/anaconda3/envs/capstone/lib/python3.8/site-packages/wandb/sdk/lib/sock_client.py", line 154, in send_server_request
    self._send_message(msg)
  File "/opt/homebrew/anaconda3/envs/capstone/lib/python3.8/site-packages/wandb/sdk/lib/sock_client.py", line 151, in _send_message
    self._sendall_with_error_handle(header + data)
  File "/opt/homebrew/anaconda3/envs/capstone/lib/python3.8/site-packages/wandb/sdk/lib/sock_client.py", line 130, in _sendall_with_error_handle
    sent = self._sock.send(data)
BrokenPipeError: [Errno 32] Broken pipe
2025-03-30 02:00:59,464 ERROR   MainThread:83519 [redirect.py:_on_write():661] error in stderr callback
Traceback (most recent call last):
  File "/opt/homebrew/anaconda3/envs/capstone/lib/python3.8/site-packages/wandb/sdk/lib/redirect.py", line 659, in _on_write
    cb(written_data)
  File "/opt/homebrew/anaconda3/envs/capstone/lib/python3.8/site-packages/wandb/sdk/wandb_run.py", line 2302, in <lambda>
    lambda data: self._console_raw_callback("stderr", data),
  File "/opt/homebrew/anaconda3/envs/capstone/lib/python3.8/site-packages/wandb/sdk/wandb_run.py", line 401, in wrapper_fn
    return func(self, *args, **kwargs)
  File "/opt/homebrew/anaconda3/envs/capstone/lib/python3.8/site-packages/wandb/sdk/wandb_run.py", line 1444, in _console_raw_callback
    self._backend.interface.publish_output_raw(name, data)
  File "/opt/homebrew/anaconda3/envs/capstone/lib/python3.8/site-packages/wandb/sdk/interface/interface.py", line 761, in publish_output_raw
    self._publish_output_raw(o)
  File "/opt/homebrew/anaconda3/envs/capstone/lib/python3.8/site-packages/wandb/sdk/interface/interface_shared.py", line 38, in _publish_output_raw
    self._publish(rec)
  File "/opt/homebrew/anaconda3/envs/capstone/lib/python3.8/site-packages/wandb/sdk/interface/interface_sock.py", line 39, in _publish
    self._sock_client.send_record_publish(record)
  File "/opt/homebrew/anaconda3/envs/capstone/lib/python3.8/site-packages/wandb/sdk/lib/sock_client.py", line 174, in send_record_publish
    self.send_server_request(server_req)
  File "/opt/homebrew/anaconda3/envs/capstone/lib/python3.8/site-packages/wandb/sdk/lib/sock_client.py", line 154, in send_server_request
    self._send_message(msg)
  File "/opt/homebrew/anaconda3/envs/capstone/lib/python3.8/site-packages/wandb/sdk/lib/sock_client.py", line 151, in _send_message
    self._sendall_with_error_handle(header + data)
  File "/opt/homebrew/anaconda3/envs/capstone/lib/python3.8/site-packages/wandb/sdk/lib/sock_client.py", line 130, in _sendall_with_error_handle
    sent = self._sock.send(data)
BrokenPipeError: [Errno 32] Broken pipe
2025-03-30 02:00:59,465 ERROR   MainThread:83519 [redirect.py:_on_write():661] error in stderr callback
Traceback (most recent call last):
  File "/opt/homebrew/anaconda3/envs/capstone/lib/python3.8/site-packages/wandb/sdk/lib/redirect.py", line 659, in _on_write
    cb(written_data)
  File "/opt/homebrew/anaconda3/envs/capstone/lib/python3.8/site-packages/wandb/sdk/wandb_run.py", line 2302, in <lambda>
    lambda data: self._console_raw_callback("stderr", data),
  File "/opt/homebrew/anaconda3/envs/capstone/lib/python3.8/site-packages/wandb/sdk/wandb_run.py", line 401, in wrapper_fn
    return func(self, *args, **kwargs)
  File "/opt/homebrew/anaconda3/envs/capstone/lib/python3.8/site-packages/wandb/sdk/wandb_run.py", line 1444, in _console_raw_callback
    self._backend.interface.publish_output_raw(name, data)
  File "/opt/homebrew/anaconda3/envs/capstone/lib/python3.8/site-packages/wandb/sdk/interface/interface.py", line 761, in publish_output_raw
    self._publish_output_raw(o)
  File "/opt/homebrew/anaconda3/envs/capstone/lib/python3.8/site-packages/wandb/sdk/interface/interface_shared.py", line 38, in _publish_output_raw
    self._publish(rec)
  File "/opt/homebrew/anaconda3/envs/capstone/lib/python3.8/site-packages/wandb/sdk/interface/interface_sock.py", line 39, in _publish
    self._sock_client.send_record_publish(record)
  File "/opt/homebrew/anaconda3/envs/capstone/lib/python3.8/site-packages/wandb/sdk/lib/sock_client.py", line 174, in send_record_publish
    self.send_server_request(server_req)
  File "/opt/homebrew/anaconda3/envs/capstone/lib/python3.8/site-packages/wandb/sdk/lib/sock_client.py", line 154, in send_server_request
    self._send_message(msg)
  File "/opt/homebrew/anaconda3/envs/capstone/lib/python3.8/site-packages/wandb/sdk/lib/sock_client.py", line 151, in _send_message
    self._sendall_with_error_handle(header + data)
  File "/opt/homebrew/anaconda3/envs/capstone/lib/python3.8/site-packages/wandb/sdk/lib/sock_client.py", line 130, in _sendall_with_error_handle
    sent = self._sock.send(data)
BrokenPipeError: [Errno 32] Broken pipe
2025-03-30 02:00:59,465 ERROR   MainThread:83519 [redirect.py:_on_write():661] error in stderr callback
Traceback (most recent call last):
  File "/opt/homebrew/anaconda3/envs/capstone/lib/python3.8/site-packages/wandb/sdk/lib/redirect.py", line 659, in _on_write
    cb(written_data)
  File "/opt/homebrew/anaconda3/envs/capstone/lib/python3.8/site-packages/wandb/sdk/wandb_run.py", line 2302, in <lambda>
    lambda data: self._console_raw_callback("stderr", data),
  File "/opt/homebrew/anaconda3/envs/capstone/lib/python3.8/site-packages/wandb/sdk/wandb_run.py", line 401, in wrapper_fn
    return func(self, *args, **kwargs)
  File "/opt/homebrew/anaconda3/envs/capstone/lib/python3.8/site-packages/wandb/sdk/wandb_run.py", line 1444, in _console_raw_callback
    self._backend.interface.publish_output_raw(name, data)
  File "/opt/homebrew/anaconda3/envs/capstone/lib/python3.8/site-packages/wandb/sdk/interface/interface.py", line 761, in publish_output_raw
    self._publish_output_raw(o)
  File "/opt/homebrew/anaconda3/envs/capstone/lib/python3.8/site-packages/wandb/sdk/interface/interface_shared.py", line 38, in _publish_output_raw
    self._publish(rec)
  File "/opt/homebrew/anaconda3/envs/capstone/lib/python3.8/site-packages/wandb/sdk/interface/interface_sock.py", line 39, in _publish
    self._sock_client.send_record_publish(record)
  File "/opt/homebrew/anaconda3/envs/capstone/lib/python3.8/site-packages/wandb/sdk/lib/sock_client.py", line 174, in send_record_publish
    self.send_server_request(server_req)
  File "/opt/homebrew/anaconda3/envs/capstone/lib/python3.8/site-packages/wandb/sdk/lib/sock_client.py", line 154, in send_server_request
    self._send_message(msg)
  File "/opt/homebrew/anaconda3/envs/capstone/lib/python3.8/site-packages/wandb/sdk/lib/sock_client.py", line 151, in _send_message
    self._sendall_with_error_handle(header + data)
  File "/opt/homebrew/anaconda3/envs/capstone/lib/python3.8/site-packages/wandb/sdk/lib/sock_client.py", line 130, in _sendall_with_error_handle
    sent = self._sock.send(data)
BrokenPipeError: [Errno 32] Broken pipe
2025-03-30 02:00:59,465 ERROR   MainThread:83519 [redirect.py:_on_write():661] error in stderr callback
Traceback (most recent call last):
  File "/opt/homebrew/anaconda3/envs/capstone/lib/python3.8/site-packages/wandb/sdk/lib/redirect.py", line 659, in _on_write
    cb(written_data)
  File "/opt/homebrew/anaconda3/envs/capstone/lib/python3.8/site-packages/wandb/sdk/wandb_run.py", line 2302, in <lambda>
    lambda data: self._console_raw_callback("stderr", data),
  File "/opt/homebrew/anaconda3/envs/capstone/lib/python3.8/site-packages/wandb/sdk/wandb_run.py", line 401, in wrapper_fn
    return func(self, *args, **kwargs)
  File "/opt/homebrew/anaconda3/envs/capstone/lib/python3.8/site-packages/wandb/sdk/wandb_run.py", line 1444, in _console_raw_callback
    self._backend.interface.publish_output_raw(name, data)
  File "/opt/homebrew/anaconda3/envs/capstone/lib/python3.8/site-packages/wandb/sdk/interface/interface.py", line 761, in publish_output_raw
    self._publish_output_raw(o)
  File "/opt/homebrew/anaconda3/envs/capstone/lib/python3.8/site-packages/wandb/sdk/interface/interface_shared.py", line 38, in _publish_output_raw
    self._publish(rec)
  File "/opt/homebrew/anaconda3/envs/capstone/lib/python3.8/site-packages/wandb/sdk/interface/interface_sock.py", line 39, in _publish
    self._sock_client.send_record_publish(record)
  File "/opt/homebrew/anaconda3/envs/capstone/lib/python3.8/site-packages/wandb/sdk/lib/sock_client.py", line 174, in send_record_publish
    self.send_server_request(server_req)
  File "/opt/homebrew/anaconda3/envs/capstone/lib/python3.8/site-packages/wandb/sdk/lib/sock_client.py", line 154, in send_server_request
    self._send_message(msg)
  File "/opt/homebrew/anaconda3/envs/capstone/lib/python3.8/site-packages/wandb/sdk/lib/sock_client.py", line 151, in _send_message
    self._sendall_with_error_handle(header + data)
  File "/opt/homebrew/anaconda3/envs/capstone/lib/python3.8/site-packages/wandb/sdk/lib/sock_client.py", line 130, in _sendall_with_error_handle
    sent = self._sock.send(data)
BrokenPipeError: [Errno 32] Broken pipe
2025-03-30 02:00:59,466 ERROR   MainThread:83519 [redirect.py:_on_write():661] error in stderr callback
Traceback (most recent call last):
  File "/opt/homebrew/anaconda3/envs/capstone/lib/python3.8/site-packages/wandb/sdk/lib/redirect.py", line 659, in _on_write
    cb(written_data)
  File "/opt/homebrew/anaconda3/envs/capstone/lib/python3.8/site-packages/wandb/sdk/wandb_run.py", line 2302, in <lambda>
    lambda data: self._console_raw_callback("stderr", data),
  File "/opt/homebrew/anaconda3/envs/capstone/lib/python3.8/site-packages/wandb/sdk/wandb_run.py", line 401, in wrapper_fn
    return func(self, *args, **kwargs)
  File "/opt/homebrew/anaconda3/envs/capstone/lib/python3.8/site-packages/wandb/sdk/wandb_run.py", line 1444, in _console_raw_callback
    self._backend.interface.publish_output_raw(name, data)
  File "/opt/homebrew/anaconda3/envs/capstone/lib/python3.8/site-packages/wandb/sdk/interface/interface.py", line 761, in publish_output_raw
    self._publish_output_raw(o)
  File "/opt/homebrew/anaconda3/envs/capstone/lib/python3.8/site-packages/wandb/sdk/interface/interface_shared.py", line 38, in _publish_output_raw
    self._publish(rec)
  File "/opt/homebrew/anaconda3/envs/capstone/lib/python3.8/site-packages/wandb/sdk/interface/interface_sock.py", line 39, in _publish
    self._sock_client.send_record_publish(record)
  File "/opt/homebrew/anaconda3/envs/capstone/lib/python3.8/site-packages/wandb/sdk/lib/sock_client.py", line 174, in send_record_publish
    self.send_server_request(server_req)
  File "/opt/homebrew/anaconda3/envs/capstone/lib/python3.8/site-packages/wandb/sdk/lib/sock_client.py", line 154, in send_server_request
    self._send_message(msg)
  File "/opt/homebrew/anaconda3/envs/capstone/lib/python3.8/site-packages/wandb/sdk/lib/sock_client.py", line 151, in _send_message
    self._sendall_with_error_handle(header + data)
  File "/opt/homebrew/anaconda3/envs/capstone/lib/python3.8/site-packages/wandb/sdk/lib/sock_client.py", line 130, in _sendall_with_error_handle
    sent = self._sock.send(data)
BrokenPipeError: [Errno 32] Broken pipe
2025-03-30 02:00:59,466 ERROR   MainThread:83519 [redirect.py:_on_write():661] error in stderr callback
Traceback (most recent call last):
  File "/opt/homebrew/anaconda3/envs/capstone/lib/python3.8/site-packages/wandb/sdk/lib/redirect.py", line 659, in _on_write
    cb(written_data)
  File "/opt/homebrew/anaconda3/envs/capstone/lib/python3.8/site-packages/wandb/sdk/wandb_run.py", line 2302, in <lambda>
    lambda data: self._console_raw_callback("stderr", data),
  File "/opt/homebrew/anaconda3/envs/capstone/lib/python3.8/site-packages/wandb/sdk/wandb_run.py", line 401, in wrapper_fn
    return func(self, *args, **kwargs)
  File "/opt/homebrew/anaconda3/envs/capstone/lib/python3.8/site-packages/wandb/sdk/wandb_run.py", line 1444, in _console_raw_callback
    self._backend.interface.publish_output_raw(name, data)
  File "/opt/homebrew/anaconda3/envs/capstone/lib/python3.8/site-packages/wandb/sdk/interface/interface.py", line 761, in publish_output_raw
    self._publish_output_raw(o)
  File "/opt/homebrew/anaconda3/envs/capstone/lib/python3.8/site-packages/wandb/sdk/interface/interface_shared.py", line 38, in _publish_output_raw
    self._publish(rec)
  File "/opt/homebrew/anaconda3/envs/capstone/lib/python3.8/site-packages/wandb/sdk/interface/interface_sock.py", line 39, in _publish
    self._sock_client.send_record_publish(record)
  File "/opt/homebrew/anaconda3/envs/capstone/lib/python3.8/site-packages/wandb/sdk/lib/sock_client.py", line 174, in send_record_publish
    self.send_server_request(server_req)
  File "/opt/homebrew/anaconda3/envs/capstone/lib/python3.8/site-packages/wandb/sdk/lib/sock_client.py", line 154, in send_server_request
    self._send_message(msg)
  File "/opt/homebrew/anaconda3/envs/capstone/lib/python3.8/site-packages/wandb/sdk/lib/sock_client.py", line 151, in _send_message
    self._sendall_with_error_handle(header + data)
  File "/opt/homebrew/anaconda3/envs/capstone/lib/python3.8/site-packages/wandb/sdk/lib/sock_client.py", line 130, in _sendall_with_error_handle
    sent = self._sock.send(data)
BrokenPipeError: [Errno 32] Broken pipe
2025-03-30 02:00:59,467 ERROR   MainThread:83519 [redirect.py:_on_write():661] error in stderr callback
Traceback (most recent call last):
  File "/opt/homebrew/anaconda3/envs/capstone/lib/python3.8/site-packages/wandb/sdk/lib/redirect.py", line 659, in _on_write
    cb(written_data)
  File "/opt/homebrew/anaconda3/envs/capstone/lib/python3.8/site-packages/wandb/sdk/wandb_run.py", line 2302, in <lambda>
    lambda data: self._console_raw_callback("stderr", data),
  File "/opt/homebrew/anaconda3/envs/capstone/lib/python3.8/site-packages/wandb/sdk/wandb_run.py", line 401, in wrapper_fn
    return func(self, *args, **kwargs)
  File "/opt/homebrew/anaconda3/envs/capstone/lib/python3.8/site-packages/wandb/sdk/wandb_run.py", line 1444, in _console_raw_callback
    self._backend.interface.publish_output_raw(name, data)
  File "/opt/homebrew/anaconda3/envs/capstone/lib/python3.8/site-packages/wandb/sdk/interface/interface.py", line 761, in publish_output_raw
    self._publish_output_raw(o)
  File "/opt/homebrew/anaconda3/envs/capstone/lib/python3.8/site-packages/wandb/sdk/interface/interface_shared.py", line 38, in _publish_output_raw
    self._publish(rec)
  File "/opt/homebrew/anaconda3/envs/capstone/lib/python3.8/site-packages/wandb/sdk/interface/interface_sock.py", line 39, in _publish
    self._sock_client.send_record_publish(record)
  File "/opt/homebrew/anaconda3/envs/capstone/lib/python3.8/site-packages/wandb/sdk/lib/sock_client.py", line 174, in send_record_publish
    self.send_server_request(server_req)
  File "/opt/homebrew/anaconda3/envs/capstone/lib/python3.8/site-packages/wandb/sdk/lib/sock_client.py", line 154, in send_server_request
    self._send_message(msg)
  File "/opt/homebrew/anaconda3/envs/capstone/lib/python3.8/site-packages/wandb/sdk/lib/sock_client.py", line 151, in _send_message
    self._sendall_with_error_handle(header + data)
  File "/opt/homebrew/anaconda3/envs/capstone/lib/python3.8/site-packages/wandb/sdk/lib/sock_client.py", line 130, in _sendall_with_error_handle
    sent = self._sock.send(data)
BrokenPipeError: [Errno 32] Broken pipe
2025-03-30 02:00:59,467 ERROR   MainThread:83519 [redirect.py:_on_write():661] error in stderr callback
Traceback (most recent call last):
  File "/opt/homebrew/anaconda3/envs/capstone/lib/python3.8/site-packages/wandb/sdk/lib/redirect.py", line 659, in _on_write
    cb(written_data)
  File "/opt/homebrew/anaconda3/envs/capstone/lib/python3.8/site-packages/wandb/sdk/wandb_run.py", line 2302, in <lambda>
    lambda data: self._console_raw_callback("stderr", data),
  File "/opt/homebrew/anaconda3/envs/capstone/lib/python3.8/site-packages/wandb/sdk/wandb_run.py", line 401, in wrapper_fn
    return func(self, *args, **kwargs)
  File "/opt/homebrew/anaconda3/envs/capstone/lib/python3.8/site-packages/wandb/sdk/wandb_run.py", line 1444, in _console_raw_callback
    self._backend.interface.publish_output_raw(name, data)
  File "/opt/homebrew/anaconda3/envs/capstone/lib/python3.8/site-packages/wandb/sdk/interface/interface.py", line 761, in publish_output_raw
    self._publish_output_raw(o)
  File "/opt/homebrew/anaconda3/envs/capstone/lib/python3.8/site-packages/wandb/sdk/interface/interface_shared.py", line 38, in _publish_output_raw
    self._publish(rec)
  File "/opt/homebrew/anaconda3/envs/capstone/lib/python3.8/site-packages/wandb/sdk/interface/interface_sock.py", line 39, in _publish
    self._sock_client.send_record_publish(record)
  File "/opt/homebrew/anaconda3/envs/capstone/lib/python3.8/site-packages/wandb/sdk/lib/sock_client.py", line 174, in send_record_publish
    self.send_server_request(server_req)
  File "/opt/homebrew/anaconda3/envs/capstone/lib/python3.8/site-packages/wandb/sdk/lib/sock_client.py", line 154, in send_server_request
    self._send_message(msg)
  File "/opt/homebrew/anaconda3/envs/capstone/lib/python3.8/site-packages/wandb/sdk/lib/sock_client.py", line 151, in _send_message
    self._sendall_with_error_handle(header + data)
  File "/opt/homebrew/anaconda3/envs/capstone/lib/python3.8/site-packages/wandb/sdk/lib/sock_client.py", line 130, in _sendall_with_error_handle
    sent = self._sock.send(data)
BrokenPipeError: [Errno 32] Broken pipe
2025-03-30 02:00:59,467 ERROR   MainThread:83519 [redirect.py:_on_write():661] error in stderr callback
Traceback (most recent call last):
  File "/opt/homebrew/anaconda3/envs/capstone/lib/python3.8/site-packages/wandb/sdk/lib/redirect.py", line 659, in _on_write
    cb(written_data)
  File "/opt/homebrew/anaconda3/envs/capstone/lib/python3.8/site-packages/wandb/sdk/wandb_run.py", line 2302, in <lambda>
    lambda data: self._console_raw_callback("stderr", data),
  File "/opt/homebrew/anaconda3/envs/capstone/lib/python3.8/site-packages/wandb/sdk/wandb_run.py", line 401, in wrapper_fn
    return func(self, *args, **kwargs)
  File "/opt/homebrew/anaconda3/envs/capstone/lib/python3.8/site-packages/wandb/sdk/wandb_run.py", line 1444, in _console_raw_callback
    self._backend.interface.publish_output_raw(name, data)
  File "/opt/homebrew/anaconda3/envs/capstone/lib/python3.8/site-packages/wandb/sdk/interface/interface.py", line 761, in publish_output_raw
    self._publish_output_raw(o)
  File "/opt/homebrew/anaconda3/envs/capstone/lib/python3.8/site-packages/wandb/sdk/interface/interface_shared.py", line 38, in _publish_output_raw
    self._publish(rec)
  File "/opt/homebrew/anaconda3/envs/capstone/lib/python3.8/site-packages/wandb/sdk/interface/interface_sock.py", line 39, in _publish
    self._sock_client.send_record_publish(record)
  File "/opt/homebrew/anaconda3/envs/capstone/lib/python3.8/site-packages/wandb/sdk/lib/sock_client.py", line 174, in send_record_publish
    self.send_server_request(server_req)
  File "/opt/homebrew/anaconda3/envs/capstone/lib/python3.8/site-packages/wandb/sdk/lib/sock_client.py", line 154, in send_server_request
    self._send_message(msg)
  File "/opt/homebrew/anaconda3/envs/capstone/lib/python3.8/site-packages/wandb/sdk/lib/sock_client.py", line 151, in _send_message
    self._sendall_with_error_handle(header + data)
  File "/opt/homebrew/anaconda3/envs/capstone/lib/python3.8/site-packages/wandb/sdk/lib/sock_client.py", line 130, in _sendall_with_error_handle
    sent = self._sock.send(data)
BrokenPipeError: [Errno 32] Broken pipe
2025-03-30 02:00:59,467 ERROR   MainThread:83519 [redirect.py:_on_write():661] error in stderr callback
Traceback (most recent call last):
  File "/opt/homebrew/anaconda3/envs/capstone/lib/python3.8/site-packages/wandb/sdk/lib/redirect.py", line 659, in _on_write
    cb(written_data)
  File "/opt/homebrew/anaconda3/envs/capstone/lib/python3.8/site-packages/wandb/sdk/wandb_run.py", line 2302, in <lambda>
    lambda data: self._console_raw_callback("stderr", data),
  File "/opt/homebrew/anaconda3/envs/capstone/lib/python3.8/site-packages/wandb/sdk/wandb_run.py", line 401, in wrapper_fn
    return func(self, *args, **kwargs)
  File "/opt/homebrew/anaconda3/envs/capstone/lib/python3.8/site-packages/wandb/sdk/wandb_run.py", line 1444, in _console_raw_callback
    self._backend.interface.publish_output_raw(name, data)
  File "/opt/homebrew/anaconda3/envs/capstone/lib/python3.8/site-packages/wandb/sdk/interface/interface.py", line 761, in publish_output_raw
    self._publish_output_raw(o)
  File "/opt/homebrew/anaconda3/envs/capstone/lib/python3.8/site-packages/wandb/sdk/interface/interface_shared.py", line 38, in _publish_output_raw
    self._publish(rec)
  File "/opt/homebrew/anaconda3/envs/capstone/lib/python3.8/site-packages/wandb/sdk/interface/interface_sock.py", line 39, in _publish
    self._sock_client.send_record_publish(record)
  File "/opt/homebrew/anaconda3/envs/capstone/lib/python3.8/site-packages/wandb/sdk/lib/sock_client.py", line 174, in send_record_publish
    self.send_server_request(server_req)
  File "/opt/homebrew/anaconda3/envs/capstone/lib/python3.8/site-packages/wandb/sdk/lib/sock_client.py", line 154, in send_server_request
    self._send_message(msg)
  File "/opt/homebrew/anaconda3/envs/capstone/lib/python3.8/site-packages/wandb/sdk/lib/sock_client.py", line 151, in _send_message
    self._sendall_with_error_handle(header + data)
  File "/opt/homebrew/anaconda3/envs/capstone/lib/python3.8/site-packages/wandb/sdk/lib/sock_client.py", line 130, in _sendall_with_error_handle
    sent = self._sock.send(data)
BrokenPipeError: [Errno 32] Broken pipe
2025-03-30 02:00:59,467 ERROR   MainThread:83519 [redirect.py:_on_write():661] error in stderr callback
Traceback (most recent call last):
  File "/opt/homebrew/anaconda3/envs/capstone/lib/python3.8/site-packages/wandb/sdk/lib/redirect.py", line 659, in _on_write
    cb(written_data)
  File "/opt/homebrew/anaconda3/envs/capstone/lib/python3.8/site-packages/wandb/sdk/wandb_run.py", line 2302, in <lambda>
    lambda data: self._console_raw_callback("stderr", data),
  File "/opt/homebrew/anaconda3/envs/capstone/lib/python3.8/site-packages/wandb/sdk/wandb_run.py", line 401, in wrapper_fn
    return func(self, *args, **kwargs)
  File "/opt/homebrew/anaconda3/envs/capstone/lib/python3.8/site-packages/wandb/sdk/wandb_run.py", line 1444, in _console_raw_callback
    self._backend.interface.publish_output_raw(name, data)
  File "/opt/homebrew/anaconda3/envs/capstone/lib/python3.8/site-packages/wandb/sdk/interface/interface.py", line 761, in publish_output_raw
    self._publish_output_raw(o)
  File "/opt/homebrew/anaconda3/envs/capstone/lib/python3.8/site-packages/wandb/sdk/interface/interface_shared.py", line 38, in _publish_output_raw
    self._publish(rec)
  File "/opt/homebrew/anaconda3/envs/capstone/lib/python3.8/site-packages/wandb/sdk/interface/interface_sock.py", line 39, in _publish
    self._sock_client.send_record_publish(record)
  File "/opt/homebrew/anaconda3/envs/capstone/lib/python3.8/site-packages/wandb/sdk/lib/sock_client.py", line 174, in send_record_publish
    self.send_server_request(server_req)
  File "/opt/homebrew/anaconda3/envs/capstone/lib/python3.8/site-packages/wandb/sdk/lib/sock_client.py", line 154, in send_server_request
    self._send_message(msg)
  File "/opt/homebrew/anaconda3/envs/capstone/lib/python3.8/site-packages/wandb/sdk/lib/sock_client.py", line 151, in _send_message
    self._sendall_with_error_handle(header + data)
  File "/opt/homebrew/anaconda3/envs/capstone/lib/python3.8/site-packages/wandb/sdk/lib/sock_client.py", line 130, in _sendall_with_error_handle
    sent = self._sock.send(data)
BrokenPipeError: [Errno 32] Broken pipe
